Workbook

Sheet Summary
A1: VOLT-FORGE appendix
A2: The numbers behind the Round 1 slide. Tata Elxsi Teliport Season 4, Case Study 2. Results are simulated; nothing has been built.
A4: Headlines
A5: Number | B5: Value | C5: What it means
A6: Smallest design that qualifies, cells | B6: ='Design study'!A16 -> 2 | C6: Two LG M50T cells with the far-cell output, among the parallel layouts tested
A7: Required Pi tests passed | B7: ='Design study'!D16 -> 33 | C7: Out of 33: normal, weak cell in each position, low cooling and more
A8: Worst cell current, A | B8: ='Design study'!I16 -> 5.3284255 | C8: Against a 7.275 A limit
A9: Cell cost for 2 cells, ₹ | B9: =Parts!C16 -> 2412 | C9: Half the ₹4,824 of the four-cell start. Cells only
A10: Simulated cases | B10: ='Design study'!I28 -> 4006 | C10: Frozen plan, run once, every result kept
A11: Nearest cell, real share of current at the start, % | B11: =Evidence!B48 -> 33.61321 | C11: Published four-cell test. The model predicted 34.4
A12: Farthest cell, real share of current at the start, % | B12: =Evidence!B51 -> 18.752242 | C12: Same test. The model predicted 18.7
A13: Measured cases inside both bands | B13: =Evidence!I31 -> 0 | C13: Out of 12 full-discharge checks. Voltage and temperature both missed. The model was not tuned
A14: Highest real over model heating, first 10 minutes | B14: =Evidence!D64 -> 1.1341301 | C14: Eight measured discharges, the length of the Pi job
A15: Cost to build the full product, ₹ crore | B15: ='Build cost'!B49 -> 35.38284 | C15: Three years, from own lab data to a full engineering app
A16: Person-years | B16: ='Build cost'!H23 -> 100.5 | C16: About 34 people on average
A17: Share of one AspenTech R&D year | B17: ='Build cost'!B68 -> 0.019507541 | C17: Scale check against an established engineering software company
A18: TAM, students (lakh) | B18: =Market!B18 -> 41.31303 | C18: All engineering and technology students in India
A19: SAM, students (lakh) | B19: =Market!B19 -> 15.55323 | C19: Electrical, electronics and mechanical
A20: SOM, colleges | B20: =Market!B20 -> 130 | C20: Assumed 5% of engineering colleges
A21: First stage of the build, ₹ crore | B21: =Market!B37 -> 10.971354 | C21: Dataset, results, quality and the lab
A22: Paying teams to repay it in 5 years | B22: =Market!E37 -> 31 | C22: At an assumed ₹5 lakh a year, plus 130 labs, before running costs
A24: Tabs
A25: Build cost | B25: Every workstream, salary, lab item and running cost, plus two cross-checks
A26: Market | B26: TAM, SAM, SOM, the staged business case and what it takes to repay it
A27: Parts | B27: Listings and cost at each cell count, with the matching board
A28: Design study | B28: All 13 designs and what argues against the answer
A29: Evidence | B29: Software checks, real measurements, and whether the error changes the decision
A30: Limits and sources | B30: What is untested, bench safety, and where each number came from
A32: Colour key
A33: Blue text | B33: An input you can change
A34: Black text | B34: A formula or a recorded result
A35: Green text | B35: Pulled from another tab
A36: Yellow fill | B36: Our assumption, not a sourced number

Sheet Build cost
A1: What the full product would cost to build
A2: About ₹35 crore over three years. Estimate, not a quote. Change any blue cell and everything follows.
A4: Inputs
A5: Overhead on salary | B5: 1.4 | C5: Employer costs, hardware, office, hiring, attrition
A6: Contingency | B6: 0.2 | C6: A research-heavy build carries schedule risk
A7: ₹ per US$ | B7: 88 | C7: Planning rate
A8: Duration, years | B8: 3
A10: Work breakdown, in person-years
A11: Workstream | B11: Vision section | C11: Principal | D11: Senior physics | E11: Senior software | F11: Engineer | G11: Test technician | H11: Person-years | I11: ₹ lakh | J11: ₹ crore
A12: Pay, ₹ lakh a year | C12: 37 | D12: 25 | E12: 18.1 | F12: 11 | G12: 8
A13: Measured dataset and validation | B13: Sections 7, 12 | C13: 0.5 | D13: 3 | E13: 0 | F13: 3 | G13: 6 | H13: =SUM(C13:G13) -> 12.5 | I13: =SUMPRODUCT($C$12:$G$12,C13:G13)*$B$5 -> 244.3 | J13: =I13/100 -> 2.443
A14: Electrical and thermal solvers to pack scale | B14: Sections 6, 13 | C14: 1 | D14: 6 | E14: 3 | F14: 0 | G14: 0 | H14: =SUM(C14:G14) -> 10 | I14: =SUMPRODUCT($C$12:$G$12,C14:G14)*$B$5 -> 337.82 | J14: =I14/100 -> 3.3782
A15: Electrochemistry, CFD and FEA | B15: Section 13 extensions | C15: 1 | D15: 8 | E15: 3 | F15: 0 | G15: 0 | H15: =SUM(C15:G15) -> 12 | I15: =SUMPRODUCT($C$12:$G$12,C15:G15)*$B$5 -> 407.82 | J15: =I15/100 -> 4.0782
A16: 3D Design Studio and CAD exchange | B16: Sections 4, 11 | C16: 1 | D16: 0 | E16: 10 | F16: 6 | G16: 0 | H16: =SUM(C16:G16) -> 17 | I16: =SUMPRODUCT($C$12:$G$12,C16:G16)*$B$5 -> 397.6 | J16: =I16/100 -> 3.976
A17: Component library and versioned model graph | B17: Sections 5, 13 | C17: 0 | D17: 1 | E17: 4 | F17: 4 | G17: 0 | H17: =SUM(C17:G17) -> 9 | I17: =SUMPRODUCT($C$12:$G$12,C17:G17)*$B$5 -> 197.96 | J17: =I17/100 -> 1.9796
A18: Simulation, results, failure search and comparison | B18: Sections 6 to 9 | C18: 0 | D18: 2 | E18: 6 | F18: 4 | G18: 0 | H18: =SUM(C18:G18) -> 12 | I18: =SUMPRODUCT($C$12:$G$12,C18:G18)*$B$5 -> 283.64 | J18: =I18/100 -> 2.8364
A19: AI copilot | B19: Section 10 | C19: 0 | D19: 0 | E19: 2 | F19: 1 | G19: 0 | H19: =SUM(C19:G19) -> 3 | I19: =SUMPRODUCT($C$12:$G$12,C19:G19)*$B$5 -> 66.08 | J19: =I19/100 -> 0.6608
A20: Reports, projects, collaboration and security | B20: Sections 3, 11, 14 | C20: 0 | D20: 0 | E20: 5 | F20: 5 | G20: 0 | H20: =SUM(C20:G20) -> 10 | I20: =SUMPRODUCT($C$12:$G$12,C20:G20)*$B$5 -> 203.7 | J20: =I20/100 -> 2.037
A21: Quality, documentation and support | B21: Sections 12, 14 | C21: 0 | D21: 0 | E21: 0 | F21: 6 | G21: 3 | H21: =SUM(C21:G21) -> 9 | I21: =SUMPRODUCT($C$12:$G$12,C21:G21)*$B$5 -> 126 | J21: =I21/100 -> 1.26
A22: Product, design and management | B22: All | C22: 3 | D22: 0 | E22: 3 | F22: 0 | G22: 0 | H22: =SUM(C22:G22) -> 6 | I22: =SUMPRODUCT($C$12:$G$12,C22:G22)*$B$5 -> 231.42 | J22: =I22/100 -> 2.3142
A23: Total people | H23: =SUM(H13:H22) -> 100.5 | I23: =SUM(I13:I22) -> 2496.34 | J23: =SUM(J13:J22) -> 24.9634
A25: Lab
A26: Item | B26: Basis | C26: Quantity | D26: Unit ₹ | E26: Unit US$ | F26: ₹ lakh
A27: LG M50T cells | B27: sourced | C27: 500 | D27: 1206 | F27: =C27*IF(D27<>"",D27,E27*$B$7)/100000 -> 6.03
A28: Neware 8-channel 5 V 6 A cyclers | B28: sourced | C28: 5 | E28: 3000 | F28: =C28*IF(D28<>"",D28,E28*$B$7)/100000 -> 13.2
A29: High-current module cyclers | B29: assumed | C29: 4 | D29: 1200000 | F29: =C29*IF(D29<>"",D29,E29*$B$7)/100000 -> 48
A30: Sub-zero thermal chambers | B30: assumed | C30: 4 | D30: 500000 | F30: =C30*IF(D30<>"",D30,E30*$B$7)/100000 -> 20
A31: Sensors, fixtures and safety equipment | B31: assumed | C31: 1 | D31: 1500000 | F31: =C31*IF(D31<>"",D31,E31*$B$7)/100000 -> 15
A32: Total lab | F32: =SUM(F27:F31) -> 102.23
A34: Running costs (all assumed)
A35: Item | B35: Basis | C35: ₹ lakh a year | D35: ₹ lakh total
A36: Lab space, power and safety | B36: assumed | C36: 30 | D36: =C36*$B$8 -> 90
A37: Cloud and compute | B37: assumed | C37: 40 | D37: =C37*$B$8 -> 120
A38: Software tools and AI usage | B38: assumed | C38: 30 | D38: =C38*$B$8 -> 90
A39: Total running | D39: =SUM(D36:D38) -> 300
A40: Legal, IP and quality audits (one-off) | B40: assumed | D40: 50
A42: Total
A43: Layer | B43: ₹ crore | C43: Share
A44: People | B44: =I23/100 -> 24.9634 | C44: =B44/$B$49 -> 0.70552279
A45: Lab | B45: =F32/100 -> 1.0223 | C45: =B45/$B$49 -> 0.028892537
...

Sheet Market
A1: Who could use it, India first
A2: Students use it free, so revenue comes from labs and teams. Counts size the audience; they do not show anyone will pay.
A4: From AISHE 2021-22 (Ministry of Education)
A5: Group | B5: Count | C5: Note
A6: Engineering and technology students | B6: 4131303
A7: Electronics students | B7: 605023
A8: Mechanical students | B8: 574940
A9: Electrical students | B9: 375360
A10: Engineering and technology colleges | B10: 2610 | C10: 2,610 of 42,825 responding colleges are specialised in Engineering & Technology. Universities and non-responding colleges are not counted.
A12: Assumed, nobody has seen this price
A13: Lab licence, ₹ a year | B13: 50000 | C13: Placeholder price for the free-for-students, paid-for-labs hypothesis. No customer has seen this price.
A14: Share of colleges reached | B14: 0.05 | C14: Placeholder reach for the first three years. Not based on adoption data.
A16: Result
A17: Level | B17: Value | C17: What it is
A18: TAM, students (lakh) | B18: =B6/100000 -> 41.31303 | C18: All engineering and technology students
A19: SAM, students (lakh) | B19: =SUM(B7:B9)/100000 -> 15.55323 | C19: Electrical, electronics and mechanical students, the branches that design battery systems
A20: SOM, colleges | B20: =ROUNDDOWN(B10*B14,0) -> 130 | C20: Assumed 5% of engineering colleges buying one lab licence, rounded down
A21: SOM revenue, ₹ lakh a year | B21: =B20*B13/100000 -> 65
A23: Honest finding
A24: Years of SOM revenue to repay the build | B24: ='Build cost'!B49*100/B21 -> 54.435138 | C24: Lab licences alone will not repay a ₹35 crore build, so the plan needs paying engineering teams and a staged build.
A26: Business case (hypothesis, no customer has seen these prices)
A27: Free for students. Labs pay a yearly licence. Engineering teams pay a yearly team plan.
A28: MATLAB, US$ | B28: 2625
A29: Simulink, US$ | B29: 3965
A30: Simscape, US$ | B30: 2625
A31: Simscape Battery, US$ | B31: 3965
A32: One commercial seat today, ₹ lakh | B32: =SUM(B28:B31)*'Build cost'!$B$7/100000 -> 11.5984 | C32: One seat of the nearest commercial stack. Perpetual, named user, North America Standard, September 2026, excluding tax.
A33: Team plan, ₹ a year | B33: 500000 | C33: One team, up to five seats. Placeholder set below one seat of the benchmark stack. Not tested with any customer.
A34: Years to repay | B34: 5 | C34: Planning horizon for the first stage.
A36: Stage | B36: Cost, ₹ crore | C36: What is in it | D36: Running total, ₹ crore | E36: Paying teams needed
A37: 1. Validated tool for labs and small teams | B37: =('Build cost'!J13+'Build cost'!J18+'Build cost'!J21+('Build cost'!F32+'Build cost'!D36)/100+('Build cost'!D39-'Build cost'!D36+'Build cost'!D40)/100*('Build cost'!J13+'Build cost'!J18+'Build cost'!J21)/'Build cost'!J23)*(1+'Build cost'!$B$6) -> 10.971354 | C37: Measured dataset and validation, Simulation, results, failure search and comparison, Quality, documentation and support | D37: =SUM(B$37:B37) -> 10.971354 | E37: =ROUNDUP(MAX(0,(D37*100/$B$34-$B$21)*100000/$B$33),0) -> 31
A38: 2. Pack scale for larger teams | B38: =('Build cost'!J14+'Build cost'!J17+'Build cost'!J19+'Build cost'!J20+0+('Build cost'!D39-'Build cost'!D36+'Build cost'!D40)/100*('Build cost'!J14+'Build cost'!J17+'Build cost'!J19+'Build cost'!J20)/'Build cost'!J23)*(1+'Build cost'!$B$6) -> 10.673533 | C38: Electrical and thermal solvers to pack scale, Component library and versioned model graph, AI copilot, Reports, projects, collaboration and security | D38: =SUM(B$37:B38) -> 21.644887 | E38: =ROUNDUP(MAX(0,(D38*100/$B$34-$B$21)*100000/$B$33),0) -> 74
A39: 3. Full engineering suite | B39: =('Build cost'!J15+'Build cost'!J16+'Build cost'!J22+0+('Build cost'!D39-'Build cost'!D36+'Build cost'!D40)/100*('Build cost'!J15+'Build cost'!J16+'Build cost'!J22)/'Build cost'!J23)*(1+'Build cost'!$B$6) -> 13.737953 | C39: Electrochemistry, CFD and FEA, 3D Design Studio and CAD exchange, Product, design and management | D39: =SUM(B$37:B39) -> 35.38284 | E39: =ROUNDUP(MAX(0,(D39*100/$B$34-$B$21)*100000/$B$33),0) -> 129
A40: Stage one carries all lab equipment and lab running costs. Other shared costs are split by people cost, and contingency is added to each stage. Each stage starts only if the one before it is paying. Repayment leaves out running, support and sales costs after the build, and assumes customers from day one. The number of paying teams in India has not been sized.
A42: Stage one, needed a year, ₹ crore | B42: =B37/B34 -> 2.1942707
A43: Paying teams needed with no lab income | B43: =ROUNDUP(B37*10000000/B34/B33,0) -> 44
A44: Labs needed with no team income | B44: =ROUNDUP(B37*10000000/B34/B13,0) -> 439 | C44: Against 2,610 colleges, so labs alone are unlikely to carry it.

Sheet Parts
A1: What the backup would cost in parts
A2: Public listings checked 30 Oct 2026. One exact part per line. Two cells halve the cell bill, not the whole unit.
A4: Listings
A5: Part | B5: Seller | C5: Price | D5: Currency | E5: Tax | F5: Availability | G5: Note
A6: LG INR21700-M50T cell | B6: Robu | C6: 1206 | D6: INR | E6: Includes GST | F6: Out of stock | G6: Listing includes GST. Listed as out of stock when checked.
A7: Samsung INR21700-30T cell | B7: IMR Batteries | C7: 6.99 | D7: USD | E7: Not stated | F7: Listed | G7: US listing. Not converted to rupees.
A8: ETP copper | B8: B B Electrotechnic | C8: 920 | D8: INR | E8: Not stated | F8: Indicative | G8: Indicative rate per kg for a 12 mm busbar. Not a quote for thin fabricated links.
A9: Geekworm X1205 2-cell UPS HAT | B9: Geekworm | C9: 46 | D9: USD | E9: Not stated | F9: Contradictory on the page | G9: Batteries, shipping and import duty not included. The page showed both "Only 118 items in stock" and "Out of stock". Lists up to 95% efficiency and a 2.4 V over-discharge cutoff on v1.1. No battery overcurrent threshold is published.
A10: Geekworm X1206 V2.0 UPS board | B10: Geekworm | C10: 52 | D10: USD | E10: Not stated | F10: Contradictory on the page | G10: Batteries, shipping and import duty not included. The page showed both "Only 37 items in stock" and "Out of stock". No battery-side cutoff or efficiency is published, and the listing does not confirm running with fewer than four cells fitted.
A11: Battery protection | G11: Included in the UPS board. The maker lists battery overcurrent, overvoltage and reverse-cell protection, with a 2.4 V over-discharge cutoff on v1.1. Not certified or independently tested here.
A13: Cost by cell count
A14: Cells | B14: Mass, g | C14: Cells, ₹ | D14: Board, ₹ | E14: Cells + board, ₹ | F14: Saving against 4 cells | G14: Note
A15: 1 | B15: =A15*$B$19 -> 70 | C15: =A15*$C$6 -> 1206 | D15: =$C$10*'Build cost'!$B$7 -> 4576 | E15: =C15+D15 -> 5782 | F15: =1-E15/$E$18 -> 0.38489362 | G15: Refused: over the cell current limit
A16: 2 | B16: =A16*$B$19 -> 140 | C16: =A16*$C$6 -> 2412 | D16: =$C$9*'Build cost'!$B$7 -> 4048 | E16: =C16+D16 -> 6460 | F16: =1-E16/$E$18 -> 0.31276596 | G16: Recommended, on the 2-cell X1205 board
A17: 3 | B17: =A17*$B$19 -> 210 | C17: =A17*$C$6 -> 3618 | D17: =$C$10*'Build cost'!$B$7 -> 4576 | E17: =C17+D17 -> 8194 | F17: =1-E17/$E$18 -> 0.12829787 | G17: The maker does not confirm the 4-cell board with three cells
A18: 4 | B18: =A18*$B$19 -> 280 | C18: =A18*$C$6 -> 4824 | D18: =$C$10*'Build cost'!$B$7 -> 4576 | E18: =C18+D18 -> 9400 | F18: =1-E18/$E$18 -> 0 | G18: Starting design, on the 4-cell X1206 board
A19: Mass per cell, g | B19: 70
A20: Cells + board leaves out shipping, import duty, links and enclosure. Only in-stock near match found: M50LT at ₹499 from Hubtronics, a different cell we have not modelled.

Sheet Design study
A1: How few cells can back up a Raspberry Pi 5?
A2: Two. 4,006 simulated cases, frozen before the first run. Every row is a design; the blue row is the recommendation.
A4: The job
A5: Pi load, W | C5: 25
A6: Converter efficiency | C6: 0.9
A7: Voltage floor, V | C7: 3.3
A8: Cell current limit, A | C8: 7.275
A9: Battery current held, A | C9: =$C$5/$C$6/$C$7 -> 8.4175084 | D9: Constant-current stand-in for a constant-power load, for 10 minutes at 23 °C
A11: Results
A12: Cells | B12: Output layout | C12: Verdict | D12: Required passed | E12: Required total | F12: Lowest V, normal | G12: Peak A, normal | H12: Lowest V, worst | I12: Peak A, worst | J12: Worst °C | K12: Spare A | L12: 12 A stress samples passed
A13: 1 | B13: Same end | C13: Refused | D13: 0 | E13: 15
A14: 2 | B14: Same end | C14: Qualifies | D14: 33 | E14: 33 | F14: 3.5277795 | G14: 4.3738908 | H14: 3.4989723 | I14: 5.485359 | J14: 31.776411 | K14: =$C$8-I14 -> 1.789641 | L14: 59 of 62
A15: 2 | B15: Far cell, thicker links | C15: Qualifies | D15: 33 | E15: 33 | F15: 3.5266152 | G15: 4.2087542 | H15: 3.4983393 | I15: 5.3453849 | J15: 31.537769 | K15: =$C$8-I15 -> 1.9296151 | L15: 60 of 62
A16: 2 | B16: Far cell | C16: Qualifies | D16: 33 | E16: 33 | F16: 3.524959 | G16: 4.2087542 | H16: 3.4966843 | I16: 5.3284255 | J16: 31.573202 | K16: =$C$8-I16 -> 1.9465745 | L16: 60 of 62
A17: 2 | B17: Same end, thicker links | C17: Qualifies | D17: 33 | E17: 33 | F17: 3.5293731 | G17: 4.3093905 | H17: 3.5007778 | I17: 5.4409464 | J17: 31.660671 | K17: =$C$8-I17 -> 1.8340536 | L17: 59 of 62
A18: 3 | B18: Same end | C18: Qualifies | D18: 42 | E18: 42 | F18: 3.6315291 | G18: 3.1608231 | H18: 3.6155708 | I18: 3.8554804 | J18: 27.694596 | K18: =$C$8-I18 -> 3.4195196 | L18: 62 of 62
A19: 3 | B19: Far cell, thicker links | C19: Qualifies | D19: 42 | E19: 42 | F19: 3.6295535 | G19: 2.8283794 | H19: 3.6137738 | I19: 3.5309623 | J19: 27.322578 | K19: =$C$8-I19 -> 3.7440377 | L19: 62 of 62
A20: 3 | B20: Far cell | C20: Qualifies | D20: 42 | E20: 42 | F20: 3.6258652 | G20: 2.8430195 | H20: 3.6100917 | I20: 3.5376767 | J20: 27.380077 | K20: =$C$8-I20 -> 3.7373233 | L20: 62 of 62
A21: 3 | B21: Same end, thicker links | C21: Qualifies | D21: 42 | E21: 42 | F21: 3.6350475 | G21: 3.0249516 | H21: 3.6191994 | I21: 3.7275345 | J21: 27.512882 | K21: =$C$8-I21 -> 3.5474655 | L21: 62 of 62
A22: 4 | B22: Same end | C22: Qualifies | D22: 51 | E22: 51 | F22: 3.6891763 | G22: 2.6409478 | H22: 3.6638328 | I22: 3.3405013 | J22: 26.118307 | K22: =$C$8-I22 -> 3.9344987 | L22: 247 of 247
A23: 4 | B23: Far cell, thicker links | C23: Qualifies | D23: 51 | E23: 51 | F23: 3.6864014 | G23: 2.1546952 | H23: 3.6609399 | I23: 2.878501 | J23: 25.890183 | K23: =$C$8-I23 -> 4.396499 | L23: 247 of 247
A24: 4 | B24: Far cell | C24: Qualifies | D24: 51 | E24: 51 | F24: 3.6805668 | G24: 2.1869454 | H24: 3.6551191 | I24: 2.8864989 | J24: 25.922827 | K24: =$C$8-I24 -> 4.3885011 | L24: 247 of 247
A25: 4 | B25: Same end, thicker links | C25: Qualifies | D25: 51 | E25: 51 | F25: 3.694684 | G25: 2.4406845 | H25: 3.6692617 | I25: 3.1644903 | J25: 26.00758 | K25: =$C$8-I25 -> 4.1105097 | L25: 247 of 247
A27: The study at a glance
A28: Cases run | I28: 4006
A29: Refused by the product, all for going over the cell current limit | I29: 42
A30: Calculated cases, every one closed its energy balance | I30: =4006-42 -> 3964
A31: Time-step check: largest voltage change when the step was halved, V | I31: 9.5000559e-06
A32: Time-step check: largest temperature change, K | I32: 0.00096881056
A34: What argues against two cells
A35: No spare: if one cell or its contact fails, the backup fails. Three cells is the smallest design that survives losing a cell.
A36: Less margin: 5.33 A worst case, against 3.34 A for four cells.
A37: Cold rooms: below 10 °C the LG sheet limits each cell to 2.425 A, so two cells could not carry this load. The study holds 23 °C.
A38: A bought board has a fixed cell layout, so the far-cell output needs your own wiring. The same-end layout also passes all 33 required tests.
A39: The X1205 publishes no battery overcurrent threshold, so its limit at about 8 A must be measured.
A40: The 12 A stress test can fail: 2 of 62 mixed samples were refused. All 62 passed at the Pi load.
A41: No link layout wins everywhere: the far-cell output raised peak current in 35 of 81 paired cases.
A42: Temperatures are a range, not a prediction. See Evidence.
A44: If the Pi draws less than 25 W
A45: One cell stays under its limit below, W | C45: =$C$8*$C$7*$C$6 -> 21.60675 | D45: 25 W is the supply rating, not a measured draw. Published readings are about 8.8 W on a CPU stress test and up to 16 W with an SSD and video.
...

Sheet Evidence
A1: How far the results can be trusted
A2: The maths checks out. Real-data comparison did not: all 12 cases missed. We kept that result and did not tune the model.
A4: Checks
A5: Check | B5: Result | C5: What it means
A6: Python tests | B6: 442 passed, 8 known skips | C6: Clean install of the final code
A7: JavaScript tests | B7: 50 passed | C7: Editor and app logic
A8: AI route | B8: 4 of 4 prompts on Claude and on Codex | C8: Each plain-English request opened an editable draft
A9: Independent solver (PyBaMM) | B9: 15 of 15 cases | C9: Same answer on voltage and heat, so the arithmetic is sound. This is not a test against real cells
A10: Energy balance | B10: Closed in all 3,964 runs | C10: Energy out of the cells equals energy delivered plus heat
A11: Export replay | B11: 5 of 5 replayed | C11: A saved test reproduces exactly; tampered files are refused
A12: Data files | B12: 194 files hashed | C12: 54 module experiments from Piombo et al., inventory and integrity only
A13: Sealed records | B13: 9 never opened | C13: 3 module tests and 6 Samsung cell records, reserved for a final assessment
A14: Audit of V3 findings | B14: 16 fixed, 3 partly, 1 bounded | C14: Self-check of the V3 findings. VF3-08 stays unresolved but does not change the decision. A fresh reviewer then raised 26 items on V4: see INDEPENDENT_AUDIT.md
A16: Compared with published measurements: frozen before any run, never used to fit
A17: Voltage band: RMSE up to 50 mV and largest error up to 150 mV. Temperature band: peak rise error up to 1 K or 25% of the measured rise, whichever is larger.
A18: Case | B18: Role | C18: Current, A | D18: Voltage error, V | E18: Temp error, K | F18: Rise measured, K | G18: Rise simulated, K | H18: Difference, K | I18: Voltage in band | J18: Temp in band
A19: Test 28 | B19: Exact M50T module | C19: 14.561026 | D19: 0.18038965 | E19: 3.0301738 | F19: 5.3376154 | G19: 8.3968241 | H19: =G19-F19 -> 3.0592087 | I19: No | J19: No
A20: Test 28, Hall current | B20: Exact M50T module | C20: 16.108949 | D20: 0.080223457 | E20: 4.0923517 | F20: 5.1098175 | G20: 9.8613115 | H20: =G20-F20 -> 4.751494 | I20: No | J20: No
A21: Test 28, link +1 mΩ | B21: Exact M50T module | C21: 14.561026 | D21: 0.15493515 | E21: 3.3295671 | F21: 5.3376154 | G21: 9.0448592 | H21: =G21-F21 -> 3.7072439 | I21: No | J21: No
A22: Test 53 | B22: Module, already used for cooling | C22: 14.554388 | D22: 0.17291847 | E22: 3.2580469 | F22: 2.214293 | G22: 5.8297425 | H22: =G22-F22 -> 3.6154495 | I22: No | J22: No
A23: Test 53, Hall current | B23: Module, already used for cooling | C23: 12.871097 | D23: 0.052008768 | E23: 2.3556857 | F23: 3.0483614 | G23: 4.8637154 | H23: =G23-F23 -> 1.815354 | I23: No | J23: No
A24: Test 53, link +1 mΩ | B24: Module, already used for cooling | C24: 14.554388 | D24: 0.18571829 | E24: 3.5505282 | F24: 2.1993577 | G24: 6.5830861 | H24: =G24-F24 -> 4.3837284 | I24: No | J24: No
A25: Warwick cell02 2.5A | B25: Warwick M50 single cell | C25: 2.4999939 | D25: 0.067989828 | E25: 2.089402 | F25: 6.473 | G25: 2.89865 | H25: =G25-F25 -> -3.57435 | I25: No | J25: No
A26: Warwick cell02 5A | B26: Warwick M50 single cell | C26: 5.0000157 | D26: 0.093451129 | E26: 4.2445937 | F26: 15.8462 | G26: 9.2547804 | H26: =G26-F26 -> -6.5914196 | I26: No | J26: No
A27: Warwick cell03 2.5A | B27: Warwick M50 single cell | C27: 2.4999747 | D27: 0.070472729 | E27: 1.3975027 | F27: 5.8234 | G27: 3.3414733 | H27: =G27-F27 -> -2.4819267 | I27: No | J27: No
A28: Warwick cell03 5A | B28: Warwick M50 single cell | C28: 5.000039 | D28: 0.097691449 | E28: 3.0896831 | F28: 14.6949 | G28: 9.7634262 | H28: =G28-F28 -> -4.9314738 | I28: No | J28: No
A29: Warwick cell04 2.5A | B29: Warwick M50 single cell | C29: 2.4999832 | D29: 0.070734838 | E29: 2.3357141 | F29: 7.5322 | G29: 3.3208425 | H29: =G29-F29 -> -4.2113575 | I29: No | J29: No
A30: Warwick cell04 5A | B30: Warwick M50 single cell | C30: 5.0000398 | D30: 0.098711365 | E30: 5.4259786 | F30: 18.1722 | G30: 9.6499442 | H30: =G30-F30 -> -8.5222558 | I30: No | J30: No
A31: Cases inside both bands | I31: =COUNTIFS(I19:I30,"Yes",J19:J30,"Yes") -> 0 | J31: =ROWS(I19:I30) -> 12
A32: What this means: single cells heat up more than the model says, and the test rig ran cooler than it says. So cooling depends on the rig, and every temperature stays a range. Voltage also stayed outside its band.
A34: Does that error change the decision? Limits frozen before running
A35: Check | B35: Result | C35: Limit | G35: Verdict
A36: Current share, test28 | B36: 1.13 points average error | C36: 2.5 points | G36: Pass
A37: Current share, test53 | B37: 0.21 points average error | C37: 2.5 points | G37: Pass
A38: Busiest cell named, test28 | B38: 62% of samples | C38: 80% | G38: Miss
A39: Busiest cell named, test53 | B39: 48% of samples | C39: 80% | G39: Miss
A40: Voltage error in the Pi's charge range | B40: 0.17 V, model too high | C40: 0.20 V margin | G40: Pass, by 0.03 V
A41: Temperature at the worst known error | B41: 42.4 °C, at 2.27 times the rise | C41: 55 °C, LG sheet | G41: Pass
A42: 8.42 A against a true 25 W load | B42: Cell peak 4.21 A against 3.90 A | C42: Must be the harder case | G42: Pass
A43: OCV slope against entropy (VF3-08) | B43: 35.0 °C, worst variant | C43: 55 °C | G43: Pass
...

Sheet Limits and sources
A1: What is assumed, untested and where each number came from
A2: Anything marked assumed is our judgement. No user, price or accuracy claim here comes from a real trial.
A4: Not done yet
A5: Nothing has been built. All results are simulated.
A6: No hardware test and no real user trial yet. No user has tried the app.
A7: No accuracy figure exists: the published-data checks missed, and the sealed records stay closed.
A8: Not tested: Windows.
A9: The X1205 publishes no battery overcurrent threshold, so its limit at about 8 A is unknown.
A10: The LG low-charge table change is unvalidated. The Pi job never reaches it.
A11: OCV slope against entropy (VF3-08) is unresolved. It does not change the decision.
A12: Not in scope for Round 1: ageing, packaging, energy management and full charge modelling.
A13: Find the smallest design tests normal conditions only. The weak-cell tests are in the study.
... A26: Sources
A27: Number | B27: Basis | C27: Source
A28: Principal pay, ₹37 lakh | B28: sourced | C28: PERSOL India 2026 average for a senior software engineer, used here for principal-level staff https://www.persolindia.com/articles/salary-of-senior-software-engineer-in-india
A29: Senior physics pay, ₹25 lakh | B29: sourced | C29: Top of the 12 to 25 LPA band for battery simulation engineers with 3 to 5 years, EVacad https://www.evacad.com/blog/battery-modelling-simulation-in-electric-vehicles-tools-career-scope-and-industry-application
A30: Senior software pay, ₹18.1 lakh | B30: sourced | C30: Glassdoor 75th percentile, senior software engineer, India, July 2026 https://www.glassdoor.co.in/Salaries/software-engineer-senior-software-developer-salary-SRCH_KO0,43_P4.htm
A31: Engineer pay, ₹11 lakh | B31: sourced | C31: Glassdoor average, same page https://www.glassdoor.co.in/Salaries/software-engineer-senior-software-developer-salary-SRCH_KO0,43_P4.htm
A32: Test technician pay, ₹8 lakh | B32: sourced | C32: Average CTC at 2 to 5 years for design-side mechanical and CAE roles, salaryinhand https://salaryinhand.in/salaries/mechanical-engineer
A33: LG M50T cells | B33: sourced | C33: Robu listing, 30 Oct 2026
A34: Neware 8-channel 5 V 6 A cyclers | B34: sourced | C34: Midpoint of the US$2,000 to 4,000 listing on goldsupplier https://www.goldsupplier.com/provide/p159048115.html
A35: High-current module cyclers | B35: assumed | C35: Our planning figure
A36: Sub-zero thermal chambers | B36: assumed | C36: Listed 100 L chambers near Rs 1.45 lakh stop at 5 C; battery work needs sub-zero.
A37: Sensors, fixtures and safety equipment | B37: assumed | C37: Our planning figure
A38: COCOMO II formula | B38: sourced | C38: https://ranger.uta.edu/~khalili/Overview%20of%20COCOMO.htm
... A53: Single-cell test data | B53: sourced | C53: Chen et al., Warwick LG M50 data, https://wrap.warwick.ac.uk/id/eprint/149527
